Workbook
Name Base_year: #REF!
Name Borough: #REF!
Name Boundary: #REF!
Name ConFact_0.001: 'Emission & Conversion Factors'!$E$178
Name ConFact_g_to_tonnes: 'Emission & Conversion Factors'!$E$177
Name ConvFact_ttoe_to_kWh: 'Emission & Conversion Factors'!#REF!
Name EF_AD_CH4: #REF!
Name EF_ATF: #REF!
Name EF_CH4_AD: 'Emission & Conversion Factors'!#REF!
Name EF_CH4_ATF_Transport: 'Emission & Conversion Factors'!$G$37
Name EF_CH4_Coal_DCI: 'Emission & Conversion Factors'!$G$109
Name EF_CH4_Composting: 'Emission & Conversion Factors'!#REF!
Name EF_CH4_DieselAvBio_Trans_kg_l: 'Emission & Conversion Factors'!$G$46
Name EF_CH4_DieselAvBio_Transport: 'Emission & Conversion Factors'!$G$45
Name EF_CH4_ElectGen_DCI: 'Emission & Conversion Factors'!$G$123
Name EF_CH4_ElectTDL_DCI: 'Emission & Conversion Factors'!$G$124
Name EF_CH4_FuelOil_IC: 'Emission & Conversion Factors'!$G$56
Name EF_CH4_GasOil: 'Emission & Conversion Factors'!$G$60
Name EF_CH4_GasOil_RailDiesel: 'Emission & Conversion Factors'!$G$60
Name EF_CH4_Incinaration: 'Emission & Conversion Factors'!#REF!
Name EF_CH4_LPG_Transport: 'Emission & Conversion Factors'!$G$17
Name EF_CH4_NatGas_DCI: 'Emission & Conversion Factors'!$G$24
Name EF_CH4_NG_Fugitive: 'Emission & Conversion Factors'!#REF!
Name EF_CH4_PetrolAvBio_Trans_kg_l: 'Emission & Conversion Factors'!$G$70
Name EF_CH4_PetrolAvBio_Transport: 'Emission & Conversion Factors'!$G$69
Name EF_CH4_W_R_IC: 'Emission & Conversion Factors'!$E$144
Name EF_CO2_ATF_Transport: 'Emission & Conversion Factors'!$F$37
Name EF_CO2_Coal_DCI: 'Emission & Conversion Factors'!$F$109
Name EF_CO2_DieselAvBio_Trans_kg_l: 'Emission & Conversion Factors'!$F$46
Name EF_CO2_DieselAvBio_Transport: 'Emission & Conversion Factors'!$F$45
Name EF_CO2_ElectGen_DCI: 'Emission & Conversion Factors'!$F$123
Name EF_CO2_ElectTDL_DCI: 'Emission & Conversion Factors'!$F$124
Name EF_CO2_FuelOil_IC: 'Emission & Conversion Factors'!$F$56
Name EF_CO2_GasOil: 'Emission & Conversion Factors'!$F$60
Name EF_CO2_GasOil_RailDiesel: 'Emission & Conversion Factors'!$F$60
Name EF_CO2_LPG_Transport: 'Emission & Conversion Factors'!$F$17
Name EF_CO2_NatGas_DCI: 'Emission & Conversion Factors'!$F$24
Name EF_CO2_NG_Fugitive: 'Emission & Conversion Factors'!#REF!
Name EF_CO2_PetrolAvBio_Trans_kg_l: 'Emission & Conversion Factors'!$F$70
Name EF_CO2_PetrolAvBio_Transport: 'Emission & Conversion Factors'!$F$69
Name EF_CO2_Shipping: 'Emission & Conversion Factors'!#REF!
Name EF_CO2_W_R_IC: 'Emission & Conversion Factors'!$D$144
Name EF_CO2b_Incineration: 'Emission & Conversion Factors'!#REF!
Name EF_COAL_DOM: #REF!
Name EF_COAL_WORK: #REF!
Name EF_COAL_WP: #REF!
Name EF_Composting_CH4: #REF!
Name EF_Composting_N2O: #REF!
Name EF_DIESEL_LITRE: #REF!
Name EF_DIESEL_TONNE: #REF!
Name EF_ELEC: #REF!
Name EF_ELEC_GEN: #REF!
Name EF_GAS: #REF!
Name EF_GASOIL_TONNE: #REF!
Name EF_GHG_AFT: 'Emission & Conversion Factors'!$E$37
Name EF_GHG_Biomass_WoodChips: 'Emission & Conversion Factors'!$D$132
Name EF_GHG_Coal_DCI: 'Emission & Conversion Factors'!$E$109
Name EF_GHG_DieselAvBio_Trans_kg_l: 'Emission & Conversion Factors'!$E$46
Name EF_GHG_DieselAvBio_Transport: 'Emission & Conversion Factors'!$E$45
Name EF_GHG_ElectGen: 'Emission & Conversion Factors'!$E$123

Sheet About LEGGI
A1: London Energy and Greenhouse Gas Inventory (LEGGI), 2023
A3: Introduction
B4: LEGGI provides an estimate of energy consumption and GHG emissions for the Greater London area. It is produced by the Greater London Authority.
A6: Emission Sectors
B7: LEGGI provides estimates for greenhouse gases from the following sectors: I. Stationary energy II. Transport III. Waste IV. Industrial processes and product use (IPPU) V. Agriculture, forestry, and other land use (AFOLU)
A9: Greenhouse gases
B10: LEGGI estimates emissions in London of the following greenhouse gases (GHGs): • Carbon dioxide (CO2) • Methane (CH4) • Nitrous oxide (N2O) • Hydrofluorocarbons (HFCs) • Perfluorocarbons (PFCs) • Nitrogen Trifluoride (NF3) • Sulphur Hexafluoride (SF6)
A11: Geography
B12: The geographical area covered by the LEGGI includes the 32 London boroughs and the City of London. The total area covered by the LEGGI is approximately 1,579 km2.
A13: Scope of LEGGI
B14: LEGGI provides estimates of: • All Scope 1 emissions physically occurring within the city boundary. These include emissions related to fuel combustion and fugitive emissions. • Scope 2 emissions associated with the consumption of grid-supplied energy within the city boundary. Depending on where energy is generated, these emissions may physically occur inside or outside the city boundary. • Scope 3 emissions associated with the disposal or treatment of waste that is generated within the city boundary but disposed of outside the city boundary. LEGGI also provides estimates of energy consumption from domestic, industrial and commercial buildings and from transport.
A16: Data sources and method
B17: Further details on the input data and the methodology used to estimate emissions or energy consumption are provided in the Data sources and method worksheet.
A19: Change log
A20: 46007 | B20: The historic (2000-2022) emissions trajectory has been revised in the 2023 LEGGI, due to the publication of revised versions of datasets used to produce LEGGI. This means the historic emissions trajectory no longer aligns with the historic trajectory in previous versions of LEGGI. Updated input data includes: - Historic road transport energy and GHG emissions have been updated to match the latest update to the London Air Emissions Inventory, LAEI, published in 2025 - Historic IPPU trajectory has been updated following an update to government's historic dataset of common reporting tables of emissions to the UNFCCC - Historic residual fuels consumption and emissions data has been updated following an update to the government's historic dataset of subnational total final energy consumption - 2022 NRMM construction and manufacturing emissions data has been updated using the latest data available in the 2022 LAEI, published in 2025

Sheet Summary
A1: Summary of energy consumption and emissions over time in London
B2: Version | C2: Interim
B3: Publication date: | C3: 45992
A5: Key | B5: C Confirmed figures
B6: I Interim figures, to be confirmed in next version when final data is published
B7: E Estimated figure
B9: Table 0.1 Historical overview, MtCO2 (pre 2005) and MtCO2e (post 2005)
C11: CO2 Emissions (MtCO2) | I11: GHG Emissions (MtCO2e)1
C12: 1990 | D12: 2000 | E12: 2001 | F12: 2002 | G12: 2003 | H12: 2004 | I12: 2005 | J12: 2006 | K12: 2007 | L12: 2008 | M12: 2009 | N12: 2010 | O12: 2011 | P12: 2012 | Q12: 2013 | R12: 2014 | S12: 2015 | T12: 2016 | U12: 2017 | V12: 2018 | W12: 2019 | X12: 2020 | Y12: 2021 | Z12: 2022 | AA12: 2023
B13: I. ENERGY DOMESTIC | C13: E | D13: C | E13: C | F13: E | G13: C | H13: C | I13: C | J13: C | K13: C | L13: C | M13: C | N13: C | O13: C | P13: C | Q13: C | R13: C | S13: C | T13: C | U13: C | V13: C | W13: C | X13: C | Y13: C | Z13: C | AA13: I
B14: Gas | D14: 10.127455 | E14: 11.956179 | F14: =(G14-E14)/2+E14 -> 11.098927 | G14: 10.241676 | H14: 9.8750504 | I14: 9.7485891 | J14: 9.4352267 | K14: 9.2457916 | L14: 8.9878254 | M14: 8.3232087 | N14: 8.2791128 | O14: 7.7439758 | P14: 7.7059245 | Q14: 7.5744058 | R14: 7.4133159 | S14: 7.4767256 | T14: 7.4269158 | U14: 7.7069848 | V14: 7.2772942 | W14: 7.4796485 | X14: 7.874401 | Y14: 6.8366471 | Z14: 6.3431924 | AA14: ='Borough GHG'!D45 -> 6.1728839
B15: Electricity | D15: 7.358204 | E15: 5.6548758 | F15: =(G15-E15)/2+E15 -> 6.6664225 | G15: 7.6779692 | H15: 6.9152816 | I15: 6.9868968 | J15: 7.3251571 | K15: 7.3401402 | L15: 7.0320899 | M15: 6.5608748 | N15: 6.6852219 | O15: 6.467222 | P15: 7.1352389 | Q15: 6.5554593 | R15: 5.942854 | S15: 5.0173675 | T15: 3.9771513 | U15: 3.5502058 | V15: 3.1930875 | W15: 2.9013182 | X15: 2.7723644 | Y15: 2.7930257 | Z15: 2.6329804 | AA15: ='Borough GHG'!C45 -> 2.3269512
B16: Other | D16: 0.051004482 | E16: 0.18048776 | F16: 0.18472398 | G16: 0.18896019 | H16: 0.058374533
B17: Coal | I17: 0.18711599 | J17: 0.16413618 | K17: 0.16746045 | L17: 0.18111402 | M17: 0.15963575 | N17: 0.16804199 | O17: 0.16165086 | P17: 0.15752374 | Q17: 0.15902949 | R17: 0.13945715 | S17: 0.13975659 | T17: 0.13746934 | U17: 0.14041027 | V17: 0.13982902 | W17: 0.13249522 | X17: 0.12600475 | Y17: 0.125477 | Z17: 0.12994336 | AA17: ='Borough GHG'!E45 -> 0.084403921
B18: Oil | I18: 0.054958267 | J18: 0.056480194 | K18: 0.053064367 | L18: 0.053785185 | M18: 0.050996634 | N18: 0.055636307 | O18: 0.049758703 | P18: 0.050340639 | Q18: 0.051883199 | R18: 0.050142715 | S18: 0.049826371 | T18: 0.050816983 | U18: 0.049457978 | V18: 0.050176146 | W18: 0.050158863 | X18: 0.050002387 | Y18: 0.048960191 | Z18: 0.043843762 | AA18: ='Borough GHG'!F45 -> 0.045903076
B19: Bioenergy and waste (not grid connected) | I19: 0.078427207 | J19: 0.082393385 | K19: 0.075424465 | L19: 0.066665507 | M19: 0.06757952 | N19: 0.075387487 | O19: 0.072079415 | P19: 0.078276719 | Q19: 0.083148746 | R19: 0.080762741 | S19: 0.087994507 | T19: 0.092638414 | U19: 0.093853341 | V19: 0.1002251 | W19: 0.1039758 | X19: 0.10613986 | Y19: 0.11066573 | Z19: 0.10786468 | AA19: ='Borough GHG'!G45 -> 0.11313979
B20: SUB-TOTAL | C20: 15.84 | D20: =SUM(D14:D19) -> 17.536663 | E20: =SUM(E14:E19) -> 17.791542 | F20: =SUM(F14:F19) -> 17.950074 | G20: =SUM(G14:G19) -> 18.108605 | H20: =SUM(H14:H19) -> 16.848706 | I20: =SUM(I14:I19) -> 17.055987 | J20: =SUM(J14:J19) -> 17.063394 | K20: =SUM(K14:K19) -> 16.881881 | ... AA20: =SUM(AA14:AA19) -> 8.7432818
B21: Reduction from 2000 | E21: =(E20-$D$20)/$D$20 -> 0.014534064 | F21: =(F20-$D$20)/$D$20 -> 0.023574061 | G21: =(G20-$D$20)/$D$20 -> 0.032614059 | H21: =(H20-$D$20)/$D$20 -> -0.039229638 | I21: =(I20-$D$20)/$D$20 -> -0.027409779 | J21: =(J20-$D$20)/$D$20 -> -0.026987453 | K21: =(K20-$D$20)/$D$20 -> -0.037337914 | L21: =(L20-$D$20)/$D$20 -> -0.069293876 | ... AA21: =(AA20-$D$20)/$D$20 -> -0.50142843
B22: I. ENERGY INDUSTRIAL AND COMMERCIAL | C22: E | D22: C | E22: C | F22: E | G22: C | H22: C | I22: C | J22: C | K22: C | L22: C | M22: C | N22: C | O22: C | P22: C | Q22: C | R22: C | S22: C | T22: C | U22: C | V22: C | W22: C | X22: C | Y22: C | Z22: C | AA22: I
B23: Gas | D23: 6.37769 | E23: 6.1624141 | F23: =(G23-E23)/2+E23 -> 5.6663258 | G23: 5.1702375 | H23: 6.515409 | I23: 5.0402775 | J23: 4.816707 | K23: 4.5244475 | L23: 4.4953519 | M23: 4.1575652 | N23: 4.208337 | O23: 4.0189386 | P23: 3.9543804 | Q23: 3.8516188 | R23: 3.9527132 | S23: 3.7582329 | T23: 3.6757949 | U23: 3.7934088 | V23: 3.6836061 | W23: 3.6064072 | X23: 3.6678433 | Y23: 3.516367 | Z23: 3.5299195 | AA23: ='Borough GHG'!K45-'Borough GHG'!K43/1000 -> 3.3333828
B24: Electricity | D24: =16.3113908174995-D41 -> 15.332707 | E24: =14.0074473342859-E41 -> 13.167 | F24: =((G24-E24)/2+E24) -> 13.793682 | G24: =15.3408128241558-G41 -> 14.420364 | H24: =13.800344971-H41 -> 12.972324 | I24: 12.878095 | J24: 14.602348 | K24: 14.168395 | L24: 13.657477 | M24: 12.359314 | N24: 12.835405 | O24: 11.664846 | P24: 13.613146 | Q24: 12.524947 | R24: 10.969837 | S24: 9.344237 | T24: 7.186274 | U24: 6.4737662 | V24: 5.86988 | W24: 5.1878548 | X24: 3.9606135 | Y24: 4.444128 | Z24: 4.5604189 | AA24: ='Borough GHG'!J45 -> 3.8712717
B25: Large industrial gas | I25: 0.12858 | J25: 0.10432 | K25: 0.09818 | L25: 0.0987 | M25: 0.09727 | N25: 0.067887657 | O25: 0.023230612 | P25: 0.031015274 | Q25: 0.032036896 | R25: 0.019515064 | S25: 0.018515611 | T25: 0.013472645 | U25: 0.013795751 | V25: 0.010066494 | W25: 0.011014435 | X25: 0.0092972366 | Y25: 0.011540347 | Z25: 0.0087674315 | AA25: ='Borough GHG'!K43/1000 -> 0.0097394471
B26: Other | D26: 2.354 | E26: 2.4279956 | F26: 1.6425944 | G26: 0.85719326 | H26: 0.56688732
B27: Coal | I27: 0.12185946 | J27: 0.12974385 | K27: 0.11285151 | L27: 0.13075747 | M27: 0.16353192 | N27: 0.17597881 | O27: 0.16416636 | P27: 0.1849209 | Q27: 0.22733037 | R27: 0.20577487 | S27: 0.11146971 | T27: 0.10821756 | U27: 0.086933004 | V27: 0.070927574 | W27: 0.066467893 | X27: 0.060408395 | Y27: 0.053616607 | Z27: 0.05852372 | AA27: ='Borough GHG'!L45 -> 0.05825137
B28: Oil | I28: 2.9109231 | J28: 2.8197101 | K28: 2.960258 | L28: 2.285434 | M28: 2.0121878 | N28: 2.1743552 | O28: 1.9588182 | P28: 2.0730392 | Q28: 1.9487059 | R28: 1.8558085 | S28: 1.9245926 | T28: 1.9849113 | U28: 2.0065356 | V28: 2.1568264 | W28: 2.1343981 | X28: 2.0647511 | Y28: 2.1251368 | Z28: 1.9954197 | AA28: ='Borough GHG'!M45 -> 2.0459641
B29: Bioenergy and waste (not grid connected) | I29: 0.044138662 | J29: 0.054394137 | K29: 0.019489116 | L29: 0.033086161 | M29: 0.024678992 | N29: 0.035139253 | O29: 0.062947707 | P29: 0.059177581 | Q29: 0.067245097 | R29: 0.092262766 | S29: 0.087281018 | T29: 0.14287567 | U29: 0.13384496 | V29: 0.13602283 | W29: 0.12905842 | X29: 0.12667766 | Y29: 0.11501492 | Z29: 0.11436781 | AA29: ='Borough GHG'!N45 -> 0.083124727
B30: EfW (Incineration and open burning)2 | Q30: 0.0074855276 | R30: 0.0074845687 | S30: 0.00749509 | T30: 0.69243163 | U30: 0.76292036 | V30: 0.81929915 | W30: 0.87842909 | X30: 0.94384288 | Y30: 0.90408887 | Z30: 0.97776467 | AA30: =('I. Energy - Stationary'!I137+'I. Energy - Stationary'!I138)/1000000 -> 0.97350667
B31: SUB-TOTAL | C31: 19.74 | D31: =SUM(D23:D26) -> 24.064397 | E31: =SUM(E23:E26) -> 21.75741 | F31: =SUM(F23:F26) -> 21.102603 | G31: =SUM(G23:G26) -> 20.447795 | H31: =SUM(H23:H26) -> 20.054621 | I31: =SUM(I23:I29) -> 21.123874 | J31: =SUM(J23:J29) -> 22.527223 | K31: =SUM(K23:K29) -> 21.883622 | L31: =SUM(L23:L29) -> 20.700806 | M31: =SUM(M23:M29) -> 18.814548 | N31: =SUM(N23:N29) -> 19.497103 | O31: =SUM(O23:O29) -> 17.892948 | P31: =SUM(P23:P29) -> 19.91568 | ... AA31: =SUM(AA23:AA29) -> 9.4017341
B32: Reduction from 2000 | E32: =(E31-$D$31)/$D$31 -> -0.095867231 | F32: =(F31-$D$31)/$D$31 -> -0.12307787 | G32: =(G31-$D$31)/$D$31 -> -0.15028851 | H32: =(H31-$D$31)/$D$31 -> -0.16662693 | I32: =(I31-$D$31)/$D$31 -> -0.12219395 | J32: =(J31-$D$31)/$D$31 -> -0.06387755 | K32: =(K31-$D$31)/$D$31 -> -0.090622501 | L32: =(L31-$D$31)/$D$31 -> -0.13977458 | ... AA32: =(AA31-$D$31)/$D$31 -> -0.60930939
B33: I. STATIONARY ENERGY: FUGITIVE | C33: E | D33: C | E33: C | F33: E | G33: C | H33: C | I33: C | J33: C | K33: C | L33: C | M33: C | N33: C | O33: C | P33: C | Q33: C | R33: C | S33: C | T33: C | U33: C | V33: C | W33: C | X33: C | Y33: C | Z33: C | AA33: I
B34: Energy Domestic | I34: 0.16501703 | J34: 0.15971266 | K34: 0.15650604 | L34: 0.15213938 | M34: 0.14088923 | N34: 0.1401428 | O34: 0.13191774 | P34: 0.13060742 | Q34: 0.12874232 | R34: 0.12631244 | S34: 0.12728217 | T34: 0.12657168 | U34: 0.13100998 | V34: 0.12408249 | W34: 0.12802712 | X34: 0.1371502 | Y34: 0.11907541 | Z34: 0.10872906 | AA34: =AA36*AA14/(AA14+AA23+AA25) -> 0.10577509
B35: Energy Industrial and Commercial | I35: 0.085318154 | J35: 0.081533715 | K35: 0.076586559 | L35: 0.07609405 | M35: 0.070376242 | N35: 0.07123567 | O35: 0.068462158 | P35: 0.067022642 | Q35: 0.06546604 | R35: 0.067348653 | S35: 0.06397935 | T35: 0.062643976 | U35: 0.064483636 | V35: 0.062807824 | W35: 0.061729899 | X35: 0.063883648 | Y35: 0.061245352 | Z35: 0.060656853 | AA35: =AA36-AA34 -> 0.057285873
B36: SUB-TOTAL | D36: 0.28091629 | E36: 0.30837705 | F36: 0.19115925 | G36: 0.26230958 | H36: 0.26341697 | I36: =SUM(I34:I35) -> 0.25033519 | J36: =SUM(J34:J35) -> 0.24124638 | K36: =SUM(K34:K35) -> 0.2330926 | L36: =SUM(L34:L35) -> 0.22823343 | M36: =SUM(M34:M35) -> 0.21126547 | N36: =SUM(N34:N35) -> 0.21137847 | O36: =SUM(O34:O35) -> 0.2003799 | P36: =SUM(P34:P35) -> 0.19763006 | ... Z36: =SUM(Z34:Z35) -> 0.16938591 | AA36: ='Borough GHG'!AD45 -> 0.16306096
B37: SUB-TOTAL: STATIONARY ENERGY | C37: =C20+C31+C36 -> 35.58 | D37: =D20+D31+D36 -> 41.881977 | E37: =E20+E31+E36 -> 39.85733 | F37: =F20+F31+F36 -> 39.243836 | G37: =G20+G31+G36 -> 38.81871 | H37: =H20+H31+H36 -> 37.166744 | I37: =I20+I31+I36 -> 38.430196 | J37: =J20+J31+J36 -> 39.831863 | ... AA37: =AA20+AA31+AA36 -> 18.308077
B38: II. TRANSPORT | C38: E | D38: C | E38: C | F38: E | G38: C | H38: C | I38: C | J38: C | K38: E | L38: C | M38: E | N38: C | O38: E | P38: E | Q38: C | R38: E | S38: E | T38: C | U38: E | V38: E | W38: C | X38: E | Y38: E | Z38: C | AA38: I | AD38: Please note that there was a change in methodology to calculate CO2 emissions from transport between the period 2010-2012 and 2013. The most significant change was to road transport (change from a 'Defra Company Reporting' approach to a methodology in line with the National Atmospheric Emissions Inventory). Direct comparison of CO2 emissions between these years is therefore not advised. Transport emissions for 2013, 2016 and 2019 data have been updated following the latest publication of LAEI (2019). Transport emissions for interim years (2014, 2015, 2017, 2018, 2020, 2021) have been interpolated.
B39: Road transport (non electric) | C39: 7.219858 | D39: 6.623 | E39: 7.0018641 | F39: =(G39-E39)/2+E39 -> 7.2403405 | G39: 7.478817 | H39: 7.431636 | I39: 7.6692772 | J39: 7.6722846 | K39: 7.5908621 | L39: 7.5094396 | M39: 7.192674 | N39: 6.8759084 | O39: 7.1157785 | P39: 7.3556487 | Q39: 7.5955189 | R39: 7.5615349 | S39: 7.5339015 | T39: 7.6385427 | U39: 7.4159348 | V39: 7.24292 | W39: 7.1131957 | X39: 5.8352005 | Y39: 6.1949064 | Z39: 6.7893788 | AA39: ='Borough GHG'!T45 -> 6.6461607
B40: Rail_diesel | C40: 1.3867859 | D40: 0.2432247 | E40: 0.70016122 | F40: =(G40-E40)/2+E40 -> 0.84057263 | G40: 0.98098404 | H40: 0.18596729 | I40: 0.191546 | J40: 0.19154632 | K40: =J40 -> 0.19154632 | L40: 0.28214885 | M40: =L40 -> 0.28214885 | N40: 0.11117351 | O40: 0.11117351 | P40: 0.11117351 | Q40: 0.13313119 | R40: 0.13938504 | S40: 0.14281102 | T40: 0.14679734 | U40: 0.12523685 | V40: 0.11414421 | W40: 0.10310807 | X40: 0.082381428 | Y40: 0.086885035 | Z40: 0.083413987 | AA40: ='Borough GHG'!R45 -> 0.084619158
B41: Rail_electric | D41: 0.97868345 | E41: 0.84044684 | F41: 0.8804478 | G41: 0.92044877 | H41: 0.8280207 | I41: 0.98461406 | J41: 0.97870266 | K41: =J41 -> 0.97870266 | L41: 1.2372607 | M41: =L41 -> 1.2372607 | N41: 1.1844945 | O41: 1.1844945 | P41: 1.1844945 | Q41: 1.1727702 | R41: 1.055314 | S41: 0.9047495 | T41: 0.72446202 | U41: 0.66866135 | V41: 0.62395685 | W41: 0.58182967 | X41: 0.46578215 | Y41: 0.50423397 | Z41: 0.53408925 | AA41: ='Borough GHG'!S45 -> 0.45528491
B42: Road transport (electric) | V42: 0.012885128 | W42: 0.017839615 | X42: 0.035136843 | Y42: 0.050961459 | Z42: 0.0900329 | AA42: ='Borough GHG'!U45 -> 0.12035522
B43: Aviation | C43: 0.8576528 | D43: 0.856 | E43: 0.76137405 | F43: =(G43-E43)/2+E43 -> 0.91406118 | G43: 1.0667483 | H43: 1.2012669 | I43: 1.356815 | J43: 1.356815 | K43: =J43 -> 1.356815 | L43: 1.3870149 | M43: =L43 -> 1.3870149 | N43: 0.87113931 | O43: 0.87113931 | P43: 0.87113931 | Q43: 0.92907839 | R43: 0.94123027 | S43: 0.95338215 | T43: 0.96553403 | U43: 0.9571225 | V43: 0.94871097 | W43: 0.94029945 | X43: 0.3986001 | Y43: 0.36859634 | Z43: 0.67580003 | AA43: ='Borough GHG'!P45 -> 0.81117214
...

Sheet Borough kWh
A1: Borough Energy consumption - Building and Transport
A2: 2023
B4: Table B.1 Energy consumption by borough, 2023 (kWh)
B6: Total Energy Consumption | C6: Sector | W6: Grand Total
C7: Domestic | I7: Industrial and Commercial | P7: Transport
C8: Electricity | D8: Gas | E8: Coal | F8: Oil | G8: Bioenergy and waste* | H8: Total | I8: Electricity | J8: Electricity w/o transport | K8: Gas | L8: Coal | M8: Oil | N8: Bioenergy and waste* | O8: Total | P8: Aviation | Q8: Shipping | R8: Railways_Diesel | S8: Railways_Electric | T8: Road Transport - fossil fuels | U8: Road Transport - electric | V8: Total
B9: Year | C9: 2023 | D9: 2023 | E9: 2023 | F9: 2023 | G9: 2023 | I9: 2023 | J9: 2023 | K9: 2023 | L9: 2023 | M9: 2023 | N9: 2023 | P9: 2023 | Q9: 2023 | R9: 2023 | S9: 2023 | T9: 2023 | U9: 2023
B10: Barking and Dagenham | C10: ='I. Energy - Stationary'!F9 -> 2.4315867e+08 | D10: ='I. Energy - Stationary'!H9 -> 6.5140025e+08 | E10: ='I. Energy - Stationary'!J52 -> 11276408 | F10: ='I. Energy - Stationary'!K52 -> 2550489.1 | G10: ='I. Energy - Stationary'!L52 -> 29952706 | H10: =SUM(C10:G10) -> 9.3833853e+08 | I10: ='I. Energy - Stationary'!G9 -> 3.2202359e+08 | J10: =I10-S10-U10 -> 2.6164547e+08 | K10: ='I. Energy - Stationary'!I9 -> 2.2769581e+08 | L10: ='I. Energy - Stationary'!M52 -> 2902193.7 | M10: ='I. Energy - Stationary'!N52 -> 1.7161085e+08 | N10: ='I. Energy - Stationary'!O52 -> 9346576.2 | O10: =SUM(J10:N10) -> 6.732009e+08 | P10: ='II. Transport '!L9 -> 0 | Q10: ='II. Transport '!M9 -> 3896822.7 | R10: ='II. Transport '!J9 -> 10281527 | S10: ='II. Transport '!K9 -> 48222050 | T10: ='II. Transport '!S267 -> 5.5547099e+08 | U10: ='II. Transport '!AB267 -> 12156068 | V10: =SUM(P10:U10) -> 6.3002746e+08 | W10: =H10+O10+V10 -> 2.2415669e+09
B11: Barnet | C11: ='I. Energy - Stationary'!F10 -> 5.8630177e+08 | D11: ='I. Energy - Stationary'!H10 -> 1.8375564e+09 | E11: ='I. Energy - Stationary'!J53 -> 8631530.2 | F11: ='I. Energy - Stationary'!K53 -> 8375487.9 | G11: ='I. Energy - Stationary'!L53 -> 38851916 | H11: =SUM(C11:G11) -> 2.4797171e+09 | I11: ='I. Energy - Stationary'!G10 -> 4.5612902e+08 | J11: =I11-S11-U11 -> 3.2587592e+08 | K11: ='I. Energy - Stationary'!I10 -> 4.8047757e+08 | L11: ='I. Energy - Stationary'!M53 -> 6346528.5 | M11: ='I. Energy - Stationary'!N53 -> 3.3139295e+08 | N11: ='I. Energy - Stationary'!O53 -> 16434917 | O11: =SUM(J11:N11) -> 1.1605279e+09 | P11: ='II. Transport '!L10 -> 473086.03 | Q11: ='II. Transport '!M10 -> 0 | R11: ='II. Transport '!J10 -> 39301737 | S11: ='II. Transport '!K10 -> 1.0228222e+08 | T11: ='II. Transport '!S268 -> 1.3111452e+09 | U11: ='II. Transport '!AB268 -> 27970873 | V11: =SUM(P11:U11) -> 1.4811731e+09 | W11: =H11+O11+V11 -> 5.1214181e+09
B12: Bexley | C12: ='I. Energy - Stationary'!F11 -> 3.3636305e+08 | D12: ='I. Energy - Stationary'!H11 -> 1.0112982e+09 | E12: ='I. Energy - Stationary'!J54 -> 10381305 | F12: ='I. Energy - Stationary'!K54 -> 5904200.2 | G12: ='I. Energy - Stationary'!L54 -> 37702535 | H12: =SUM(C12:G12) -> 1.4016493e+09 | I12: ='I. Energy - Stationary'!G11 -> 3.9722515e+08 | J12: =I12-S12-U12 -> 3.4437365e+08 | K12: ='I. Energy - Stationary'!I11 -> 6.6332052e+08 | L12: ='I. Energy - Stationary'!M54 -> 6091027.7 | M12: ='I. Energy - Stationary'!N54 -> 1.0832232e+08 | N12: ='I. Energy - Stationary'!O54 -> 38686912 | O12: =SUM(J12:N12) -> 1.1607944e+09 | P12: ='II. Transport '!L11 -> 23379056 | Q12: ='II. Transport '!M11 -> 1769215.6 | R12: ='II. Transport '!J11 -> 4707938.6 | S12: ='II. Transport '!K11 -> 36884419 | T12: ='II. Transport '!S269 -> 7.587572e+08 | U12: ='II. Transport '!AB269 -> 15967084 | V12: =SUM(P12:U12) -> 8.4146492e+08 | W12: =H12+O12+V12 -> 3.4039087e+09
B13: Brent | C13: ='I. Energy - Stationary'!F12 -> 4.0279466e+08 | D13: ='I. Energy - Stationary'!H12 -> 1.2999263e+09 | E13: ='I. Energy - Stationary'!J55 -> 8982314.3 | F13: ='I. Energy - Stationary'!K55 -> 4883385.1 | G13: ='I. Energy - Stationary'!L55 -> 28815928 | H13: =SUM(C13:G13) -> 1.7454026e+09 | I13: ='I. Energy - Stationary'!G12 -> 7.1766426e+08 | J13: =I13-S13-U13 -> 5.8698083e+08 | K13: ='I. Energy - Stationary'!I12 -> 5.4852235e+08 | L13: ='I. Energy - Stationary'!M55 -> 7539603.8 | M13: ='I. Energy - Stationary'!N55 -> 1.8169678e+08 | N13: ='I. Energy - Stationary'!O55 -> 26035880 | O13: =SUM(J13:N13) -> 1.3507754e+09 | P13: ='II. Transport '!L12 -> 795739.37 | Q13: ='II. Transport '!M12 -> 0 | R13: ='II. Transport '!J12 -> 47170371 | S13: ='II. Transport '!K12 -> 1.119418e+08 | T13: ='II. Transport '!S270 -> 8.4251111e+08 | U13: ='II. Transport '!AB270 -> 18741632 | V13: =SUM(P13:U13) -> 1.0211607e+09 | W13: =H13+O13+V13 -> 4.1173387e+09
B14: Bromley | C14: ='I. Energy - Stationary'!F13 -> 4.9271451e+08 | D14: ='I. Energy - Stationary'!H13 -> 1.679766e+09 | E14: ='I. Energy - Stationary'!J56 -> 8546604 | F14: ='I. Energy - Stationary'!K56 -> 12924182 | G14: ='I. Energy - Stationary'!L56 -> 44204591 | H14: =SUM(C14:G14) -> 2.2381559e+09 | I14: ='I. Energy - Stationary'!G13 -> 3.5808497e+08 | J14: =I14-S14-U14 -> 2.6018379e+08 | K14: ='I. Energy - Stationary'!I13 -> 2.9366623e+08 | L14: ='I. Energy - Stationary'!M56 -> 3368202.1 | M14: ='I. Energy - Stationary'!N56 -> 1.2459416e+08 | N14: ='I. Energy - Stationary'!O56 -> 9288537.7 | O14: =SUM(J14:N14) -> 6.9110092e+08 | P14: ='II. Transport '!L13 -> 22968811 | Q14: ='II. Transport '!M13 -> 0 | R14: ='II. Transport '!J13 -> 5761664.9 | S14: ='II. Transport '!K13 -> 75626036 | T14: ='II. Transport '!S271 -> 1.0608225e+09 | U14: ='II. Transport '!AB271 -> 22275152 | V14: =SUM(P14:U14) -> 1.1874542e+09 | W14: =H14+O14+V14 -> 4.116711e+09
B15: Camden | C15: ='I. Energy - Stationary'!F14 -> 3.1778755e+08 | D15: ='I. Energy - Stationary'!H14 -> 7.9937166e+08 | E15: ='I. Energy - Stationary'!J57 -> 2143086.2 | F15: ='I. Energy - Stationary'!K57 -> 8142909.8 | G15: ='I. Energy - Stationary'!L57 -> 6070778.1 | H15: =SUM(C15:G15) -> 1.133516e+09 | I15: ='I. Energy - Stationary'!G14 -> 1.1513527e+09 | J15: =I15-S15-U15 -> 1.014374e+09 | K15: ='I. Energy - Stationary'!I14 -> 1.2923592e+09 | L15: ='I. Energy - Stationary'!M57 -> 6448478.1 | M15: ='I. Energy - Stationary'!N57 -> 6.2667415e+08 | N15: ='I. Energy - Stationary'!O57 -> 11383265 | O15: =SUM(J15:N15) -> 2.9512392e+09 | P15: ='II. Transport '!L14 -> 0 | Q15: ='II. Transport '!M14 -> 0 | R15: ='II. Transport '!J14 -> 47016888 | S15: ='II. Transport '!K14 -> 1.2218654e+08 | T15: ='II. Transport '!S272 -> 4.7525742e+08 | U15: ='II. Transport '!AB272 -> 14792071 | V15: =SUM(P15:U15) -> 6.5925292e+08 | W15: =H15+O15+V15 -> 4.7440081e+09
B16: City of London | C16: ='I. Energy - Stationary'!F15 -> 25579186 | D16: ='I. Energy - Stationary'!H15 -> 24092856 | E16: ='I. Energy - Stationary'!J58 -> 35426.036 | F16: ='I. Energy - Stationary'!K58 -> 293106.02 | G16: ='I. Energy - Stationary'!L58 -> 81249.443 | H16: =SUM(C16:G16) -> 50081824 | I16: ='I. Energy - Stationary'!G15 -> 1.5734407e+09 | J16: =I16-S16-U16 -> 1.5268344e+09 | K16: ='I. Energy - Stationary'!I15 -> 6.549078e+08 | L16: ='I. Energy - Stationary'!M58 -> 3872922 | M16: ='I. Energy - Stationary'!N58 -> 1.5322915e+08 | N16: ='I. Energy - Stationary'!O58 -> 6390979.7 | O16: =SUM(J16:N16) -> 2.3452353e+09 | P16: ='II. Transport '!L15 -> 829062.89 | Q16: ='II. Transport '!M15 -> 16385690 | R16: ='II. Transport '!J15 -> 32808.02 | S16: ='II. Transport '!K15 -> 39995269 | T16: ='II. Transport '!S273 -> 1.5420464e+08 | U16: ='II. Transport '!AB273 -> 6611010.9 | V16: =SUM(P16:U16) -> 2.1805848e+08 | W16: =H16+O16+V16 -> 2.6133756e+09
B17: Croydon | C17: ='I. Energy - Stationary'!F16 -> 5.4005014e+08 | D17: ='I. Energy - Stationary'!H16 -> 1.7271738e+09 | E17: ='I. Energy - Stationary'!J59 -> 14809139 | F17: ='I. Energy - Stationary'!K59 -> 8580262 | G17: ='I. Energy - Stationary'!L59 -> 52376010 | H17: =SUM(C17:G17) -> 2.3429893e+09 | I17: ='I. Energy - Stationary'!G16 -> 5.6540979e+08 | J17: =I17-S17-U17 -> 4.3757182e+08 | K17: ='I. Energy - Stationary'!I16 -> 4.3171691e+08 | L17: ='I. Energy - Stationary'!M59 -> 3302529.5 | M17: ='I. Energy - Stationary'!N59 -> 1.3483665e+08 | N17: ='I. Energy - Stationary'!O59 -> 9842243 | O17: =SUM(J17:N17) -> 1.0172702e+09 | P17: ='II. Transport '!L16 -> 1065532 | Q17: ='II. Transport '!M16 -> 0 | R17: ='II. Transport '!J16 -> 15009412 | S17: ='II. Transport '!K16 -> 1.0550465e+08 | T17: ='II. Transport '!S274 -> 1.0503644e+09 | U17: ='II. Transport '!AB274 -> 22333317 | V17: =SUM(P17:U17) -> 1.1942774e+09 | W17: =H17+O17+V17 -> 4.5545369e+09
B18: Ealing | C18: ='I. Energy - Stationary'!F17 -> 4.5366078e+08 | D18: ='I. Energy - Stationary'!H17 -> 1.4015725e+09 | E18: ='I. Energy - Stationary'!J60 -> 10315834 | F18: ='I. Energy - Stationary'!K60 -> 6122798.2 | G18: ='I. Energy - Stationary'!L60 -> 34518326 | H18: =SUM(C18:G18) -> 1.9061902e+09 | I18: ='I. Energy - Stationary'!G17 -> 9.0895353e+08 | J18: =I18-S18-U18 -> 7.8003226e+08 | K18: ='I. Energy - Stationary'!I17 -> 6.1999997e+08 | L18: ='I. Energy - Stationary'!M60 -> 9882170.7 | M18: ='I. Energy - Stationary'!N60 -> 2.7482888e+08 | N18: ='I. Energy - Stationary'!O60 -> 23203776 | O18: =SUM(J18:N18) -> 1.7079471e+09 | P18: ='II. Transport '!L17 -> 0 | Q18: ='II. Transport '!M17 -> 0 | R18: ='II. Transport '!J17 -> 17166640 | S18: ='II. Transport '!K17 -> 1.053774e+08 | T18: ='II. Transport '!S275 -> 1.0785477e+09 | U18: ='II. Transport '!AB275 -> 23543875 | V18: =SUM(P18:U18) -> 1.2246356e+09 | W18: =H18+O18+V18 -> 4.8387728e+09
B19: Enfield | C19: ='I. Energy - Stationary'!F18 -> 4.3739469e+08 | D19: ='I. Energy - Stationary'!H18 -> 1.318932e+09 | E19: ='I. Energy - Stationary'!J61 -> 12362140 | F19: ='I. Energy - Stationary'!K61 -> 5975865.6 | G19: ='I. Energy - Stationary'!L61 -> 38553029 | H19: =SUM(C19:G19) -> 1.8132177e+09 | I19: ='I. Energy - Stationary'!G18 -> 4.7918177e+08 | J19: =I19-S19-U19 -> 4.2217978e+08 | K19: ='I. Energy - Stationary'!I18 -> 4.694102e+08 | L19: ='I. Energy - Stationary'!M61 -> 13955225 | M19: ='I. Energy - Stationary'!N61 -> 1.5186405e+08 | N19: ='I. Energy - Stationary'!O61 -> 14804748 | O19: =SUM(J19:N19) -> 1.072214e+09 | P19: ='II. Transport '!L18 -> 814055.87 | Q19: ='II. Transport '!M18 -> 0 | R19: ='II. Transport '!J18 -> 4795865.6 | S19: ='II. Transport '!K18 -> 30339834 | T19: ='II. Transport '!S276 -> 1.525677e+09 | U19: ='II. Transport '!AB276 -> 26662162 | V19: =SUM(P19:U19) -> 1.5882889e+09 | W19: =H19+O19+V19 -> 4.4737206e+09
B20: Greenwich | C20: ='I. Energy - Stationary'!F19 -> 3.5199313e+08 | D20: ='I. Energy - Stationary'!H19 -> 9.5279921e+08 | E20: ='I. Energy - Stationary'!J62 -> 9748368.1 | F20: ='I. Energy - Stationary'!K62 -> 4544905.8 | G20: ='I. Energy - Stationary'!L62 -> 31075548 | H20: =SUM(C20:G20) -> 1.3501612e+09 | I20: ='I. Energy - Stationary'!G19 -> 4.3120639e+08 | J20: =I20-S20-U20 -> 3.5662894e+08 | K20: ='I. Energy - Stationary'!I19 -> 4.9725143e+08 | L20: ='I. Energy - Stationary'!M62 -> 4277268.5 | M20: ='I. Energy - Stationary'!N62 -> 3.2217643e+08 | N20: ='I. Energy - Stationary'!O62 -> 15699831 | O20: =SUM(J20:N20) -> 1.1960339e+09 | P20: ='II. Transport '!L19 -> 12504503 | Q20: ='II. Transport '!M19 -> 7651974.6 | R20: ='II. Transport '!J19 -> 3043080.5 | S20: ='II. Transport '!K19 -> 51284412 | T20: ='II. Transport '!S277 -> 9.6787059e+08 | U20: ='II. Transport '!AB277 -> 23293039 | V20: =SUM(P20:U20) -> 1.0656476e+09 | W20: =H20+O20+V20 -> 3.6118426e+09
B21: Hackney | C21: ='I. Energy - Stationary'!F20 -> 3.2778177e+08 | D21: ='I. Energy - Stationary'!H20 -> 8.152399e+08 | E21: ='I. Energy - Stationary'!J63 -> 3513485.2 | F21: ='I. Energy - Stationary'!K63 -> 2663991.6 | G21: ='I. Energy - Stationary'!L63 -> 8483353 | H21: =SUM(C21:G21) -> 1.1576825e+09 | I21: ='I. Energy - Stationary'!G20 -> 5.2355552e+08 | J21: =I21-S21-U21 -> 4.7816486e+08 | K21: ='I. Energy - Stationary'!I20 -> 3.5430344e+08 | L21: ='I. Energy - Stationary'!M63 -> 3551756.2 | M21: ='I. Energy - Stationary'!N63 -> 2.1997483e+08 | N21: ='I. Energy - Stationary'!O63 -> 6769783 | O21: =SUM(J21:N21) -> 1.0627647e+09 | P21: ='II. Transport '!L20 -> 0 | Q21: ='II. Transport '!M20 -> 0 | R21: ='II. Transport '!J20 -> 6565691.6 | S21: ='II. Transport '!K20 -> 33177633 | T21: ='II. Transport '!S278 -> 4.5563955e+08 | U21: ='II. Transport '!AB278 -> 12213022 | V21: =SUM(P21:U21) -> 5.075959e+08 | W21: =H21+O21+V21 -> 2.7280431e+09
... B42: Westminster | C42: ='I. Energy - Stationary'!F41 -> 4.5259893e+08 | D42: ='I. Energy - Stationary'!H41 -> 8.2004419e+08 | E42: ='I. Energy - Stationary'!J84 -> 2559806.3 | F42: ='I. Energy - Stationary'!K84 -> 10118474 | G42: ='I. Energy - Stationary'!L84 -> 6132693.5 | H42: =SUM(C42:G42) -> 1.2914541e+09 | I42: ='I. Energy - Stationary'!G41 -> 2.7487452e+09 | J42: =I42-S42-U42 -> 2.5724346e+09 | K42: ='I. Energy - Stationary'!I41 -> 2.0915073e+09 | L42: ='I. Energy - Stationary'!M84 -> 7235374.2 | M42: ='I. Energy - Stationary'!N84 -> 9.4302344e+08 | N42: ='I. Energy - Stationary'!O84 -> 10129111 | O42: =SUM(J42:N42) -> 5.6243298e+09 | P42: ='II. Transport '!L41 -> 0 | Q42: ='II. Transport '!M41 -> 11015048 | R42: ='II. Transport '!J41 -> 5413523.1 | S42: ='II. Transport '!K41 -> 1.4550898e+08 | T42: ='II. Transport '!S299 -> 7.5755602e+08 | U42: ='II. Transport '!AB299 -> 30801567 | V42: =SUM(P42:U42) -> 9.5029514e+08 | W42: =H42+O42+V42 -> 7.8660791e+09
B43: Unapportioned | J43: =I43-S43-U43 -> 0 | K43: ='I. Energy - Stationary'!I42 -> 53232658 | O43: =SUM(J43:N43) -> 53232658 | V43: =SUM(P43:U43) -> 0 | W43: =H43+O43+V43 -> 53232658
B44: Grand Total (kWh) | C44: =SUM(C10:C42) -> 1.1900129e+10 | D44: =SUM(D10:D42) -> 3.373898e+10 | E44: =SUM(E10:E42) -> 2.4309185e+08 | F44: =SUM(F10:F42) -> 1.7895936e+08 | G44: =SUM(G10:G42) -> 8.1564785e+08 | H44: =SUM(H10:H42) -> 4.6876808e+10 | I44: =SUM(I10:I42) -> 2.2741699e+10 | J44: =SUM(J10:J43) -> 1.9797851e+10 | K44: =SUM(K10:K43) -> 1.8272421e+10 | L44: =SUM(L10:L42) -> 1.6776985e+08 | M44: =SUM(M10:M42) -> 7.9764683e+09 | N44: =SUM(N10:N42) -> 5.9926311e+08 | O44: =SUM(O10:O43) -> 4.6813773e+10 | P44: =SUM(P10:P42) -> 3.4011872e+09 | Q44: =SUM(Q10:Q42) -> 90399705 | R44: =SUM(R10:R42) -> 3.2973046e+08 | S44: =SUM(S10:S42) -> 2.3283467e+09 | T44: =SUM(T10:T42) -> 2.5906117e+10 | U44: =SUM(U10:U42) -> 6.1550179e+08 | V44: =SUM(V10:V43) -> 3.2671283e+10 | W44: =H44+O44+V44 -> 1.2636186e+11
B45: Grand Total (GWh) | C45: =C44/1000000 -> 11900.129 | D45: =D44/1000000 -> 33738.98 | E45: =E44/1000000 -> 243.09185 | F45: =F44/1000000 -> 178.95936 | G45: =G44/1000000 -> 815.64785 | H45: =H44/1000000 -> 46876.808 | I45: =I44/1000000 -> 22741.699 | J45: =J44/1000000 -> 19797.851 | ... N45: =N44/1000000 -> 599.26311 | O45: =SUM(J45:N45) -> 46813.773 | P45: =P44/1000000 -> 3401.1872 | Q45: =Q44/1000000 -> 90.399705 | R45: =R44/1000000 -> 329.73046 | S45: =S44/1000000 -> 2328.3467 | T45: =T44/1000000 -> 25906.117 | U45: =U44/1000000 -> 615.50179 | V45: =V44/1000000 -> 32671.283 | W45: =H45+O45+V45 -> 126361.86
B47: *Not grid connected

Sheet Borough GHG
A1: Borough GHG emissions - Building and Transport
A2: 2023
B4: Table B.2 Greenhouse gas emissions by borough, 2023 (ktCO2e)
C6: Sector | AE6: Grand Total
C7: Domestic | I7: Industrial and Commercial | P7: Transport | W7: NRMM | AA7: IPPU | AB7: AFOLU | AC7: Waste | AD7: Fugitive emissions
C8: Electricity | D8: Gas | E8: Coal | F8: Oil | G8: Bioenergy and waste* | H8: Total | I8: Electricity | J8: Electricity w/o rail & RT | K8: Gas | L8: Coal | M8: Oil | N8: Bioenergy and waste* | O8: Total | P8: Aviation | Q8: Shipping | R8: Railways diesel | S8: Railways electric | T8: Road transport - fossil fuels | U8: Road transport - electric | V8: Total | W8: Manufacturing industries | X8: Construction | Y8: Ground activities - aviation | Z8: Total
B9: Year | C9: 2023 | D9: 2023 | E9: 2023 | F9: 2023 | G9: 2023 | I9: 2023 | J9: 2023 | K9: 2023 | L9: 2023 | M9: 2023 | N9: 2023 | P9: 2023 | Q9: 2023 | R9: 2023 | S9: 2023 | T9: 2023 | U9: 2023 | W9: 2022** | X9: 2022** | Y9: 2023 | AA9: 2023 | AB9: 2022 | AC9: 2023 | AD9: 2023 | AE9: =RIGHT($C$4,4)
B10: Barking and Dagenham | C10: ='Borough kWh'!C10*(EF_GHG_ElectGen+EF_GHG_ElectTD)/1000000 -> 47.547247 | D10: ='Borough kWh'!D10*EF_GHG_NatGas_DCI/1000000 -> 119.18019 | E10: ='Borough kWh'!E10*EF_GHG_Coal_DCI/1000000 -> 3.9152817 | F10: ='Borough kWh'!F10*EF_GHG_GasOil/1000000 -> 0.65420046 | G10: ='Borough kWh'!G10*EF_GHG_W_R_IC/1000000 -> 4.1547868 | H10: =SUM(C10:G10) -> 175.45171 | I10: ='Borough kWh'!I10*(EF_GHG_ElectGen+EF_GHG_ElectTD)/1000000 -> 62.968493 | J10: ='Borough kWh'!J10*(EF_GHG_ElectGen+EF_GHG_ElectTD)/1000000 -> 51.162156 | K10: ='Borough kWh'!K10*EF_GHG_NatGas_DCI/1000000 -> 41.659225 | L10: ='Borough kWh'!L10*EF_GHG_Coal_DCI/1000000 -> 1.0076707 | M10: ='Borough kWh'!M10*EF_GHG_GasOil/1000000 -> 44.018182 | N10: ='Borough kWh'!N10*EF_GHG_W_R_IC/1000000 -> 1.2964782 | O10: =SUM(J10:N10) -> 139.14371 | P10: ='II. Transport '!G9/1000-Y10 -> 0 | Q10: ='II. Transport '!H9/1000 -> 2.5921492 | R10: ='II. Transport '!E9/1000 -> 2.6371667 | S10: ='II. Transport '!F9/1000 -> 9.4293397 | T10: ='II. Transport '!O227/1000 -> 142.71902 | U10: ='II. Transport '!AA227/1000 -> 2.3769976 | V10: =SUM(P10:U10) -> 159.75468 | W10: ='II. Transport '!T9/1000 -> 0.64300978 | X10: ='II. Transport '!U9/1000 -> 1.9980312 | Y10: =('II. Transport '!F95+'II. Transport '!G95+'II. Transport '!K95+'II. Transport '!L95)/1000 -> 0 | Z10: =SUM(W10:Y10) -> 2.641041 | AE10: =H10+O10+V10+Z10+AC10 -> 476.99114
B11: Barnet | C11: ='Borough kWh'!C11*(EF_GHG_ElectGen+EF_GHG_ElectTD)/1000000 -> 114.64545 | D11: ='Borough kWh'!D11*EF_GHG_NatGas_DCI/1000000 -> 336.19932 | E11: ='Borough kWh'!E11*EF_GHG_Coal_DCI/1000000 -> 2.9969536 | F11: ='Borough kWh'!F11*EF_GHG_GasOil/1000000 -> 2.1483126 | G11: ='Borough kWh'!G11*EF_GHG_W_R_IC/1000000 -> 5.3892103 | H11: =SUM(C11:G11) -> 461.37925 | I11: ='Borough kWh'!I11*(EF_GHG_ElectGen+EF_GHG_ElectTD)/1000000 -> 89.191468 | J11: ='Borough kWh'!J11*(EF_GHG_ElectGen+EF_GHG_ElectTD)/1000000 -> 63.721778 | K11: ='Borough kWh'!K11*EF_GHG_NatGas_DCI/1000000 -> 87.908175 | L11: ='Borough kWh'!L11*EF_GHG_Coal_DCI/1000000 -> 2.2035782 | M11: ='Borough kWh'!M11*EF_GHG_GasOil/1000000 -> 85.002292 | N11: ='Borough kWh'!N11*EF_GHG_W_R_IC/1000000 -> 2.2797131 | O11: =SUM(J11:N11) -> 241.11554 | P11: ='II. Transport '!G10/1000-Y11 -> 0.11619417 | Q11: ='II. Transport '!H10/1000 -> 0 | R11: ='II. Transport '!E10/1000 -> 10.081621 | S11: ='II. Transport '!F10/1000 -> 20.000265 | T11: ='II. Transport '!O228/1000 -> 336.27297 | U11: ='II. Transport '!AA228/1000 -> 5.4694245 | V11: =SUM(P11:U11) -> 371.94048 | W11: ='II. Transport '!T10/1000 -> 0.50874662 | X11: ='II. Transport '!U10/1000 -> 13.866051 | Y11: =('II. Transport '!F96+'II. Transport '!G96+'II. Transport '!K96+'II. Transport '!L96)/1000 -> 0 | Z11: =(SUM(W11:Y11)) -> 14.374797 | AE11: =H11+O11+V11+Z11+AC11 -> 1088.8101
B12: Bexley | C12: ='Borough kWh'!C12*(EF_GHG_ElectGen+EF_GHG_ElectTD)/1000000 -> 65.772431 | D12: ='Borough kWh'!D12*EF_GHG_NatGas_DCI/1000000 -> 185.02712 | E12: ='Borough kWh'!E12*EF_GHG_Coal_DCI/1000000 -> 3.6044928 | F12: ='Borough kWh'!F12*EF_GHG_GasOil/1000000 -> 1.5144274 | G12: ='Borough kWh'!G12*EF_GHG_W_R_IC/1000000 -> 5.2297778 | H12: =SUM(C12:G12) -> 261.14825 | I12: ='Borough kWh'!I12*(EF_GHG_ElectGen+EF_GHG_ElectTD)/1000000 -> 77.673406 | J12: ='Borough kWh'!J12*(EF_GHG_ElectGen+EF_GHG_ElectTD)/1000000 -> 67.338823 | K12: ='Borough kWh'!K12*EF_GHG_NatGas_DCI/1000000 -> 121.36112 | L12: ='Borough kWh'!L12*EF_GHG_Coal_DCI/1000000 -> 2.1148657 | M12: ='Borough kWh'!M12*EF_GHG_GasOil/1000000 -> 27.784675 | N12: ='Borough kWh'!N12*EF_GHG_W_R_IC/1000000 -> 5.3663223 | O12: =SUM(J12:N12) -> 223.96581 | P12: ='II. Transport '!G11/1000-Y12 -> 5.7374735 | Q12: ='II. Transport '!H11/1000 -> 1.1875295 | R12: ='II. Transport '!E11/1000 -> 1.2089516 | S12: ='II. Transport '!F11/1000 -> 7.2123793 | T12: ='II. Transport '!O229/1000 -> 194.69885 | U12: ='II. Transport '!AA229/1000 -> 3.1222036 | V12: =SUM(P12:U12) -> 213.16739 | W12: ='II. Transport '!T11/1000 -> 0.48912059 | X12: ='II. Transport '!U11/1000 -> 3.4807463 | Y12: =('II. Transport '!F97+'II. Transport '!G97+'II. Transport '!K97+'II. Transport '!L97)/1000 -> 0 | Z12: =(SUM(W12:Y12)) -> 3.9698668 | AE12: =H12+O12+V12+Z12+AC12 -> 702.25132
B13: Brent | C13: ='Borough kWh'!C13*(EF_GHG_ElectGen+EF_GHG_ElectTD)/1000000 -> 78.762468 | D13: ='Borough kWh'!D13*EF_GHG_NatGas_DCI/1000000 -> 237.83451 | E13: ='Borough kWh'!E13*EF_GHG_Coal_DCI/1000000 -> 3.1187494 | F13: ='Borough kWh'!F13*EF_GHG_GasOil/1000000 -> 1.2525883 | G13: ='Borough kWh'!G13*EF_GHG_W_R_IC/1000000 -> 3.9971026 | H13: =SUM(C13:G13) -> 324.96542 | I13: ='Borough kWh'!I13*(EF_GHG_ElectGen+EF_GHG_ElectTD)/1000000 -> 140.33207 | J13: ='Borough kWh'!J13*(EF_GHG_ElectGen+EF_GHG_ElectTD)/1000000 -> 114.77823 | K13: ='Borough kWh'!K13*EF_GHG_NatGas_DCI/1000000 -> 100.35765 | L13: ='Borough kWh'!L13*EF_GHG_Coal_DCI/1000000 -> 2.6178258 | M13: ='Borough kWh'!M13*EF_GHG_GasOil/1000000 -> 46.605225 | N13: ='Borough kWh'!N13*EF_GHG_W_R_IC/1000000 -> 3.6114777 | O13: =SUM(J13:N13) -> 267.97041 | P13: ='II. Transport '!G12/1000-Y13 -> 0.19534923 | Q13: ='II. Transport '!H12/1000 -> 0 | R13: ='II. Transport '!E12/1000 -> 12.104216 | S13: ='II. Transport '!F12/1000 -> 21.8891 | T13: ='II. Transport '!O230/1000 -> 216.30288 | U13: ='II. Transport '!AA230/1000 -> 3.6647387 | V13: =SUM(P13:U13) -> 254.15628 | W13: ='II. Transport '!T12/1000 -> 0.99829727 | X13: ='II. Transport '!U12/1000 -> 13.208565 | Y13: =('II. Transport '!F98+'II. Transport '!G98+'II. Transport '!K98+'II. Transport '!L98)/1000 -> 0 | Z13: =(SUM(W13:Y13)) -> 14.206863 | AE13: =H13+O13+V13+Z13+AC13 -> 861.29897
B14: Bromley | C14: ='Borough kWh'!C14*(EF_GHG_ElectGen+EF_GHG_ElectTD)/1000000 -> 96.345396 | D14: ='Borough kWh'!D14*EF_GHG_NatGas_DCI/1000000 -> 307.32998 | E14: ='Borough kWh'!E14*EF_GHG_Coal_DCI/1000000 -> 2.9674664 | F14: ='Borough kWh'!F14*EF_GHG_GasOil/1000000 -> 3.3150526 | G14: ='Borough kWh'!G14*EF_GHG_W_R_IC/1000000 -> 6.1316881 | H14: =SUM(C14:G14) -> 416.08959 | I14: ='Borough kWh'!I14*(EF_GHG_ElectGen+EF_GHG_ElectTD)/1000000 -> 70.019936 | J14: ='Borough kWh'!J14*(EF_GHG_ElectGen+EF_GHG_ElectTD)/1000000 -> 50.876338 | K14: ='Borough kWh'!K14*EF_GHG_NatGas_DCI/1000000 -> 53.729173 | L14: ='Borough kWh'!L14*EF_GHG_Coal_DCI/1000000 -> 1.1694735 | M14: ='Borough kWh'!M14*EF_GHG_GasOil/1000000 -> 31.958403 | N14: ='Borough kWh'!N14*EF_GHG_W_R_IC/1000000 -> 1.2884276 | O14: =SUM(J14:N14) -> 139.02181 | P14: ='II. Transport '!G13/1000-Y14 -> 5.6540629 | Q14: ='II. Transport '!H13/1000 -> 0 | R14: ='II. Transport '!E13/1000 -> 1.4792363 | S14: ='II. Transport '!F13/1000 -> 14.787915 | T14: ='II. Transport '!O231/1000 -> 272.16389 | U14: ='II. Transport '!AA231/1000 -> 4.3556833 | V14: =SUM(P14:U14) -> 298.44079 | W14: ='II. Transport '!T13/1000 -> 0.30421171 | X14: ='II. Transport '!U13/1000 -> 2.4699009 | Y14: =('II. Transport '!F99+'II. Transport '!G99+'II. Transport '!K99+'II. Transport '!L99)/1000 -> 0 | Z14: =(SUM(W14:Y14)) -> 2.7741126 | AE14: =H14+O14+V14+Z14+AC14 -> 856.3263
B15: Camden | C15: ='Borough kWh'!C15*(EF_GHG_ElectGen+EF_GHG_ElectTD)/1000000 -> 62.140177 | D15: ='Borough kWh'!D15*EF_GHG_NatGas_DCI/1000000 -> 146.25304 | E15: ='Borough kWh'!E15*EF_GHG_Coal_DCI/1000000 -> 0.74410096 | F15: ='Borough kWh'!F15*EF_GHG_GasOil/1000000 -> 2.0886564 | G15: ='Borough kWh'!G15*EF_GHG_W_R_IC/1000000 -> 0.84208715 | H15: =SUM(C15:G15) -> 212.06806 | I15: ='Borough kWh'!I15*(EF_GHG_ElectGen+EF_GHG_ElectTD)/1000000 -> 225.1355 | J15: ='Borough kWh'!J15*(EF_GHG_ElectGen+EF_GHG_ElectTD)/1000000 -> 198.3507 | K15: ='Borough kWh'!K15*EF_GHG_NatGas_DCI/1000000 -> 236.45004 | L15: ='Borough kWh'!L15*EF_GHG_Coal_DCI/1000000 -> 2.2389761 | M15: ='Borough kWh'!M15*EF_GHG_GasOil/1000000 -> 160.74192 | N15: ='Borough kWh'!N15*EF_GHG_W_R_IC/1000000 -> 1.5789906 | O15: =SUM(J15:N15) -> 599.36063 | P15: ='II. Transport '!G14/1000-Y15 -> 0 | Q15: ='II. Transport '!H14/1000 -> 0 | R15: ='II. Transport '!E14/1000 -> 12.062942 | S15: ='II. Transport '!F14/1000 -> 23.892357 | T15: ='II. Transport '!O232/1000 -> 121.6665 | U15: ='II. Transport '!AA232/1000 -> 2.8924416 | V15: =SUM(P15:U15) -> 160.51424 | W15: ='II. Transport '!T14/1000 -> 1.2431013 | X15: ='II. Transport '!U14/1000 -> 66.101336 | Y15: =('II. Transport '!F100+'II. Transport '!G100+'II. Transport '!K100+'II. Transport '!L100)/1000 -> 0 | Z15: =(SUM(W15:Y15)) -> 67.344438 | AE15: =H15+O15+V15+Z15+AC15 -> 1039.2874
B16: City of London | C16: ='Borough kWh'!C16*(EF_GHG_ElectGen+EF_GHG_ElectTD)/1000000 -> 5.001754 | D16: ='Borough kWh'!D16*EF_GHG_NatGas_DCI/1000000 -> 4.408029 | E16: ='Borough kWh'!E16*EF_GHG_Coal_DCI/1000000 -> 0.012300274 | F16: ='Borough kWh'!F16*EF_GHG_GasOil/1000000 -> 0.075181695 | G16: ='Borough kWh'!G16*EF_GHG_W_R_IC/1000000 -> 0.011270238 | H16: =SUM(C16:G16) -> 9.5085352 | I16: ='Borough kWh'!I16*(EF_GHG_ElectGen+EF_GHG_ElectTD)/1000000 -> 307.67059 | J16: ='Borough kWh'!J16*(EF_GHG_ElectGen+EF_GHG_ElectTD)/1000000 -> 298.5572 | K16: ='Borough kWh'!K16*EF_GHG_NatGas_DCI/1000000 -> 119.82193 | L16: ='Borough kWh'!L16*EF_GHG_Coal_DCI/1000000 -> 1.3447173 | M16: ='Borough kWh'!M16*EF_GHG_GasOil/1000000 -> 39.303278 | N16: ='Borough kWh'!N16*EF_GHG_W_R_IC/1000000 -> 0.88650282 | O16: =SUM(J16:N16) -> 459.91363 | P16: ='II. Transport '!G15/1000-Y16 -> 0.20351953 | Q16: ='II. Transport '!H15/1000 -> 10.333671 | R16: ='II. Transport '!E15/1000 -> 0.0084247714 | S16: ='II. Transport '!F15/1000 -> 7.820675 | T16: ='II. Transport '!O233/1000 -> 39.488597 | U16: ='II. Transport '!AA233/1000 -> 1.2927171 | V16: =SUM(P16:U16) -> 59.147604 | W16: ='II. Transport '!T15/1000 -> 0.66633498 | X16: ='II. Transport '!U15/1000 -> 2.0789932 | Y16: =('II. Transport '!F101+'II. Transport '!G101+'II. Transport '!K101+'II. Transport '!L101)/1000 -> 0 | Z16: =(SUM(W16:Y16)) -> 2.7453282 | AE16: =H16+O16+V16+Z16+AC16 -> 531.3151
B17: Croydon | C17: ='Borough kWh'!C17*(EF_GHG_ElectGen+EF_GHG_ElectTD)/1000000 -> 105.6014 | D17: ='Borough kWh'!D17*EF_GHG_NatGas_DCI/1000000 -> 316.00372 | E17: ='Borough kWh'!E17*EF_GHG_Coal_DCI/1000000 -> 5.1418813 | F17: ='Borough kWh'!F17*EF_GHG_GasOil/1000000 -> 2.2008372 | G17: ='Borough kWh'!G17*EF_GHG_W_R_IC/1000000 -> 7.2651585 | H17: =SUM(C17:G17) -> 436.213 | I17: ='Borough kWh'!I17*(EF_GHG_ElectGen+EF_GHG_ElectTD)/1000000 -> 110.56023 | J17: ='Borough kWh'!J17*(EF_GHG_ElectGen+EF_GHG_ElectTD)/1000000 -> 85.562795 | K17: ='Borough kWh'!K17*EF_GHG_NatGas_DCI/1000000 -> 78.986925 | L17: ='Borough kWh'!L17*EF_GHG_Coal_DCI/1000000 -> 1.1466713 | M17: ='Borough kWh'!M17*EF_GHG_GasOil/1000000 -> 34.585601 | N17: ='Borough kWh'!N17*EF_GHG_W_R_IC/1000000 -> 1.365233 | O17: =SUM(J17:N17) -> 201.64722 | P17: ='II. Transport '!G16/1000-Y17 -> 0.2614797 | Q17: ='II. Transport '!H16/1000 -> 0 | R17: ='II. Transport '!E16/1000 -> 3.8515303 | S17: ='II. Transport '!F16/1000 -> 20.630379 | T17: ='II. Transport '!O234/1000 -> 269.58936 | U17: ='II. Transport '!AA234/1000 -> 4.3670568 | V17: =SUM(P17:U17) -> 298.69981 | W17: ='II. Transport '!T16/1000 -> 0.17657062 | X17: ='II. Transport '!U16/1000 -> 13.521726 | Y17: =('II. Transport '!F102+'II. Transport '!G102+'II. Transport '!K102+'II. Transport '!L102)/1000 -> 0 | Z17: =(SUM(W17:Y17)) -> 13.698296 | AE17: =H17+O17+V17+Z17+AC17 -> 950.25833
B18: Ealing | C18: ='Borough kWh'!C18*(EF_GHG_ElectGen+EF_GHG_ElectTD)/1000000 -> 88.708829 | D18: ='Borough kWh'!D18*EF_GHG_NatGas_DCI/1000000 -> 256.4317 | E18: ='Borough kWh'!E18*EF_GHG_Coal_DCI/1000000 -> 3.5817606 | F18: ='Borough kWh'!F18*EF_GHG_GasOil/1000000 -> 1.5704978 | G18: ='Borough kWh'!G18*EF_GHG_W_R_IC/1000000 -> 4.7880912 | H18: =SUM(C18:G18) -> 355.08088 | I18: ='Borough kWh'!I18*(EF_GHG_ElectGen+EF_GHG_ElectTD)/1000000 -> 177.73677 | J18: ='Borough kWh'!J18*(EF_GHG_ElectGen+EF_GHG_ElectTD)/1000000 -> 152.52751 | K18: ='Borough kWh'!K18*EF_GHG_NatGas_DCI/1000000 -> 113.43519 | L18: ='Borough kWh'!L18*EF_GHG_Coal_DCI/1000000 -> 3.4311885 | M18: ='Borough kWh'!M18*EF_GHG_GasOil/1000000 -> 70.493608 | N18: ='Borough kWh'!N18*EF_GHG_W_R_IC/1000000 -> 3.2186322 | O18: =SUM(J18:N18) -> 343.10613 | P18: ='II. Transport '!G17/1000-Y18 -> 0 | Q18: ='II. Transport '!H17/1000 -> 0 | R18: ='II. Transport '!E17/1000 -> 4.4069736 | S18: ='II. Transport '!F17/1000 -> 20.605496 | T18: ='II. Transport '!O235/1000 -> 276.85205 | U18: ='II. Transport '!AA235/1000 -> 4.6037693 | V18: =SUM(P18:U18) -> 306.46828 | W18: ='II. Transport '!T17/1000 -> 0.70290515 | X18: ='II. Transport '!U17/1000 -> 20.211419 | Y18: =('II. Transport '!F103+'II. Transport '!G103+'II. Transport '!K103+'II. Transport '!L103)/1000 -> 0 | Z18: =(SUM(W18:Y18)) -> 20.914324 | AE18: =H18+O18+V18+Z18+AC18 -> 1025.5696
B19: Enfield | C19: ='Borough kWh'!C19*(EF_GHG_ElectGen+EF_GHG_ElectTD)/1000000 -> 85.528158 | D19: ='Borough kWh'!D19*EF_GHG_NatGas_DCI/1000000 -> 241.3118 | E19: ='Borough kWh'!E19*EF_GHG_Coal_DCI/1000000 -> 4.2922586 | F19: ='Borough kWh'!F19*EF_GHG_GasOil/1000000 -> 1.5328095 | G19: ='Borough kWh'!G19*EF_GHG_W_R_IC/1000000 -> 5.3477511 | H19: =SUM(C19:G19) -> 338.01278 | I19: ='Borough kWh'!I19*(EF_GHG_ElectGen+EF_GHG_ElectTD)/1000000 -> 93.699203 | J19: ='Borough kWh'!J19*(EF_GHG_ElectGen+EF_GHG_ElectTD)/1000000 -> 82.553033 | K19: ='Borough kWh'!K19*EF_GHG_NatGas_DCI/1000000 -> 85.883291 | L19: ='Borough kWh'!L19*EF_GHG_Coal_DCI/1000000 -> 4.8453938 | M19: ='Borough kWh'!M19*EF_GHG_GasOil/1000000 -> 38.95313 | N19: ='Borough kWh'!N19*EF_GHG_W_R_IC/1000000 -> 2.0535898 | O19: =SUM(J19:N19) -> 214.28844 | P19: ='II. Transport '!G18/1000-Y19 -> 0.20045596 | Q19: ='II. Transport '!H18/1000 -> 0 | R19: ='II. Transport '!E18/1000 -> 1.2313567 | S19: ='II. Transport '!F18/1000 -> 5.9326511 | T19: ='II. Transport '!O236/1000 -> 392.41619 | U19: ='II. Transport '!AA236/1000 -> 5.2135191 | V19: =SUM(P19:U19) -> 404.99417 | W19: ='II. Transport '!T18/1000 -> 0.7730101 | X19: ='II. Transport '!U18/1000 -> 13.352638 | Y19: =('II. Transport '!F104+'II. Transport '!G104+'II. Transport '!K104+'II. Transport '!L104)/1000 -> 0 | Z19: =(SUM(W19:Y19)) -> 14.125648 | AE19: =H19+O19+V19+Z19+AC19 -> 971.42103
B20: Greenwich | C20: ='Borough kWh'!C20*(EF_GHG_ElectGen+EF_GHG_ElectTD)/1000000 -> 68.828736 | D20: ='Borough kWh'!D20*EF_GHG_NatGas_DCI/1000000 -> 174.32414 | E20: ='Borough kWh'!E20*EF_GHG_Coal_DCI/1000000 -> 3.3847309 | F20: ='Borough kWh'!F20*EF_GHG_GasOil/1000000 -> 1.1657683 | G20: ='Borough kWh'!G20*EF_GHG_W_R_IC/1000000 -> 4.310538 | H20: =SUM(C20:G20) -> 252.01392 | I20: ='Borough kWh'!I20*(EF_GHG_ElectGen+EF_GHG_ElectTD)/1000000 -> 84.318097 | J20: ='Borough kWh'!J20*(EF_GHG_ElectGen+EF_GHG_ElectTD)/1000000 -> 69.735223 | K20: ='Borough kWh'!K20*EF_GHG_NatGas_DCI/1000000 -> 90.977121 | L20: ='Borough kWh'!L20*EF_GHG_Coal_DCI/1000000 -> 1.4851104 | M20: ='Borough kWh'!M20*EF_GHG_GasOil/1000000 -> 82.638253 | N20: ='Borough kWh'!N20*EF_GHG_W_R_IC/1000000 -> 2.1777481 | O20: =SUM(J20:N20) -> 247.01346 | P20: ='II. Transport '!G19/1000-Y20 -> 3.0691226 | Q20: ='II. Transport '!H19/1000 -> 5.0199105 | R20: ='II. Transport '!E19/1000 -> 0.78143264 | S20: ='II. Transport '!F19/1000 -> 10.028154 | T20: ='II. Transport '!O237/1000 -> 248.41007 | U20: ='II. Transport '!AA237/1000 -> 4.5547208 | V20: =SUM(P20:U20) -> 271.86341 | W20: ='II. Transport '!T19/1000 -> 0.48605842 | X20: ='II. Transport '!U19/1000 -> 6.5119166 | Y20: =('II. Transport '!F105+'II. Transport '!G105+'II. Transport '!K105+'II. Transport '!L105)/1000 -> 0 | Z20: =(SUM(W20:Y20)) -> 6.997975 | AE20: =H20+O20+V20+Z20+AC20 -> 777.88876
B21: Hackney | C21: ='Borough kWh'!C21*(EF_GHG_ElectGen+EF_GHG_ElectTD)/1000000 -> 64.094448 | D21: ='Borough kWh'!D21*EF_GHG_NatGas_DCI/1000000 -> 149.15629 | E21: ='Borough kWh'!E21*EF_GHG_Coal_DCI/1000000 -> 1.2199172 | F21: ='Borough kWh'!F21*EF_GHG_GasOil/1000000 -> 0.68331386 | G21: ='Borough kWh'!G21*EF_GHG_W_R_IC/1000000 -> 1.1767392 | H21: =SUM(C21:G21) -> 216.33071 | I21: ='Borough kWh'!I21*(EF_GHG_ElectGen+EF_GHG_ElectTD)/1000000 -> 102.37605 | J21: ='Borough kWh'!J21*(EF_GHG_ElectGen+EF_GHG_ElectTD)/1000000 -> 93.500357 | K21: ='Borough kWh'!K21*EF_GHG_NatGas_DCI/1000000 -> 64.823357 | L21: ='Borough kWh'!L21*EF_GHG_Coal_DCI/1000000 -> 1.2332053 | M21: ='Borough kWh'!M21*EF_GHG_GasOil/1000000 -> 56.423544 | N21: ='Borough kWh'!N21*EF_GHG_W_R_IC/1000000 -> 0.93904722 | O21: =SUM(J21:N21) -> 216.91951 | P21: ='II. Transport '!G20/1000-Y21 -> 0 | Q21: ='II. Transport '!H20/1000 -> 0 | R21: ='II. Transport '!E20/1000 -> 1.686004 | S21: ='II. Transport '!F20/1000 -> 6.4875544 | T21: ='II. Transport '!O238/1000 -> 116.92931 | U21: ='II. Transport '!AA238/1000 -> 2.3881342 | V21: =SUM(P21:U21) -> 127.491 | W21: ='II. Transport '!T20/1000 -> 0.38012552 | X21: ='II. Transport '!U20/1000 -> 12.084061 | Y21: =('II. Transport '!F106+'II. Transport '!G106+'II. Transport '!K106+'II. Transport '!L106)/1000 -> 0 | Z21: =(SUM(W21:Y21)) -> 12.464186 | AE21: =H21+O21+V21+Z21+AC21 -> 573.20541
B22: Hammersmith and Fulham | C22: ='Borough kWh'!C22*(EF_GHG_ElectGen+EF_GHG_ElectTD)/1000000 -> 52.1474 | D22: ='Borough kWh'!D22*EF_GHG_NatGas_DCI/1000000 -> 134.0446 | E22: ='Borough kWh'!E22*EF_GHG_Coal_DCI/1000000 -> 1.0298153 | F22: ='Borough kWh'!F22*EF_GHG_GasOil/1000000 -> 0.82519904 | G22: ='Borough kWh'!G22*EF_GHG_W_R_IC/1000000 -> 1.0902756 | H22: =SUM(C22:G22) -> 189.13729 | I22: ='Borough kWh'!I22*(EF_GHG_ElectGen+EF_GHG_ElectTD)/1000000 -> 119.58804 | J22: ='Borough kWh'!J22*(EF_GHG_ElectGen+EF_GHG_ElectTD)/1000000 -> 107.35612 | K22: ='Borough kWh'!K22*EF_GHG_NatGas_DCI/1000000 -> 94.657787 | L22: ='Borough kWh'!L22*EF_GHG_Coal_DCI/1000000 -> 0.76441913 | M22: ='Borough kWh'!M22*EF_GHG_GasOil/1000000 -> 63.462652 | N22: ='Borough kWh'!N22*EF_GHG_W_R_IC/1000000 -> 0.79381349 | O22: =SUM(J22:N22) -> 267.03479 | P22: ='II. Transport '!G21/1000-Y22 -> 7.8664076 | Q22: ='II. Transport '!H21/1000 -> 0.0069014007 | R22: ='II. Transport '!E21/1000 -> 1.6855721 | S22: ='II. Transport '!F21/1000 -> 9.8685143 | T22: ='II. Transport '!O239/1000 -> 112.23811 | U22: ='II. Transport '!AA239/1000 -> 2.3634125 | V22: =SUM(P22:U22) -> 134.02892 | W22: ='II. Transport '!T21/1000 -> 0.34299503 | X22: ='II. Transport '!U21/1000 -> 31.502093 | Y22: =('II. Transport '!F107+'II. Transport '!G107+'II. Transport '!K107+'II. Transport '!L107)/1000 -> 0 | Z22: =(SUM(W22:Y22)) -> 31.845088 | AE22: =H22+O22+V22+Z22+AC22 -> 622.04609
... B42: Westminster | C42: ='Borough kWh'!C42*(EF_GHG_ElectGen+EF_GHG_ElectTD)/1000000 -> 88.501195 | D42: ='Borough kWh'!D42*EF_GHG_NatGas_DCI/1000000 -> 150.03529 | E42: ='Borough kWh'!E42*EF_GHG_Coal_DCI/1000000 -> 0.88879034 | F42: ='Borough kWh'!F42*EF_GHG_GasOil/1000000 -> 2.5953886 | G42: ='Borough kWh'!G42*EF_GHG_W_R_IC/1000000 -> 0.85067554 | H42: =SUM(C42:G42) -> 242.87134 | I42: ='Borough kWh'!I42*(EF_GHG_ElectGen+EF_GHG_ElectTD)/1000000 -> 537.48963 | J42: ='Borough kWh'!J42*(EF_GHG_ElectGen+EF_GHG_ElectTD)/1000000 -> 503.01386 | K42: ='Borough kWh'!K42*EF_GHG_NatGas_DCI/1000000 -> 382.66218 | L42: ='Borough kWh'!L42*EF_GHG_Coal_DCI/1000000 -> 2.5121943 | M42: ='Borough kWh'!M42*EF_GHG_GasOil/1000000 -> 241.88551 | N42: ='Borough kWh'!N42*EF_GHG_W_R_IC/1000000 -> 1.4050248 | O42: =SUM(J42:N42) -> 1131.4788 | P42: ='II. Transport '!G41/1000-Y42 -> 0 | Q42: ='II. Transport '!H41/1000 -> 7.185126 | R42: ='II. Transport '!E41/1000 -> 1.388611 | S42: ='II. Transport '!F41/1000 -> 28.452827 | T42: ='II. Transport '!O259/1000 -> 193.71981 | U42: ='II. Transport '!AA259/1000 -> 6.0229384 | V42: =SUM(P42:U42) -> 236.76931 | W42: ='II. Transport '!T41/1000 -> 2.0740798 | X42: ='II. Transport '!U41/1000 -> 20.984128 | Y42: =('II. Transport '!F127+'II. Transport '!G127+'II. Transport '!K127+'II. Transport '!L127)/1000 -> 0 | Z42: =(SUM(W42:Y42)) -> 23.058208 | AE42: =H42+O42+V42+Z42+AC42 -> 1634.1776
B43: Unapportioned | J43: =I43-S43 -> 0 | K43: ='Borough kWh'!K43*EF_GHG_NatGas_DCI/1000000 -> 9.7394471 | O43: =SUM(J43:N43) -> 9.7394471 | S43: ='II. Transport '!F42/1000 -> 0 | V43: =SUM(P43:T43) -> 0 | AA43: =SUM('IV. IPPU'!R65/1000) -> 1010.1036 | AB43: =(SUM('V. AFOLU'!H9:H18)+SUM('V. AFOLU'!H25:H42)+SUM('V. AFOLU'!H56:H61))/1000 -> 127.83062 | AC43: =('III. Waste'!L10+'III. Waste'!L20+'III. Waste'!L21+'III. Waste'!L23+'III. Waste'!L24+'III. Waste'!L35+'III. Waste'!L12+'III. Waste'!L26+'III. Waste'!L27)/1000 -> 444.54284 | AD43: ='I. Energy - Stationary'!I145/1000 -> 163.06096 | AE43: =AA43+AB43+AC43+AD43+V43+O43 -> 1755.2775
B44: Grand Total (kt) | C44: =SUM(C10:C42) -> 2326.9512 | D44: =SUM(D10:D42) -> 6172.8839 | E44: =SUM(E10:E42) -> 84.403921 | F44: =SUM(F10:F42) -> 45.903076 | G44: =SUM(G10:G42) -> 113.13979 | H44: =SUM(H10:H42) -> 8743.2818 | I44: =SUM(I10:I42) -> 4446.9118 | J44: =SUM(J10:J43) -> 3871.2717 | K44: =SUM(K10:K43) -> 3343.1222 | L44: =SUM(L10:L42) -> 58.25137 | M44: =SUM(M10:M42) -> 2045.9641 | N44: =SUM(N10:N42) -> 83.124727 | O44: =SUM(O10:O43) -> 9401.7341 | P44: =SUM(P10:P42) -> 811.17214 | Q44: =SUM(Q10:Q42) -> 58.835909 | R44: =SUM(R10:R42) -> 84.619158 | S44: =SUM(S10:S43) -> 455.28491 | T44: =SUM(T10:T42) -> 6646.1607 | U44: =SUM(U10:U42) -> 120.35522 | V44: =SUM(V10:V43) -> 8176.428 | W44: =SUM(W10:W43) -> 18.990198 | X44: =SUM(X10:X43) -> 493.10883 | Y44: =SUM(Y10:Y43) -> 31.460885 | Z44: =SUM(Z10:Z43) -> 543.55991 | AA44: =AA43 -> 1010.1036 | AB44: =AB43 -> 127.83062 | AC44: =AC43 -> 444.54284 | AD44: =AD43 -> 163.06096 | AE44: =H44+O44+V44+Z44+AA44+AB44+AC44+AD44 -> 28610.542
B45: Grand Total (mt) | C45: =C44/1000 -> 2.3269512 | D45: =D44/1000 -> 6.1728839 | E45: =E44/1000 -> 0.084403921 | F45: =F44/1000 -> 0.045903076 | G45: =G44/1000 -> 0.11313979 | H45: =H44/1000 -> 8.7432818 | I45: =I44/1000 -> 4.4469118 | J45: =J44/1000 -> 3.8712717 | ... AE45: =AE44/1000 -> 28.610542
B47: *Not grid connected
B48: **Data currently unavailable for 2023

Sheet Charts
A1: LEGGI 2023: key charts
B4: Figure 1: CO2e emissions by sector in 2023 | N4: Table C1: CO2e emissions by sector in 2023
N5: (including fugitive emissions)
N6: EMISSION SECTOR | O6: MtCO2e | P6: %
N7: Domestic | O7: =Summary!AA20+Summary!AA34 -> 8.8490569 | P7: =O7/SUM($O$7:$O$12) -> 0.30929358
N8: Industrial & Commercial | O8: =Summary!AA31+Summary!AA35 -> 9.45902 | P8: =O8/SUM($O$7:$O$12) -> 0.3306131
N9: Transport (inc. NRMM) | O9: =Summary!AA46 -> 8.7199879 | P9: =O9/SUM($O$7:$O$12) -> 0.30478234
N10: IPPU | O10: =Summary!AA56 -> 1.0101036 | P10: =O10/SUM($O$7:$O$12) -> 0.035305295
N11: Waste | O11: =Summary!AA52 -> 0.44454284 | P11: =O11/SUM($O$7:$O$12) -> 0.015537729
N12: AFOLU | O12: =Summary!AA62 -> 0.12783062 | P12: =O12/SUM($O$7:$O$12) -> 0.0044679553
B18: Figure 2: CO2e emissions for Domestic sector split by fuel in 2023 | N18: Table C2: CO2e emissions for Domestic sector split by fuel in 2023
N19: (excluding fugitive emissions)
N20: =Summary!B13 -> I. ENERGY DOMESTIC | O20: MtCO2e | P20: %
N21: =Summary!B14 -> Gas | O21: =Summary!AA14 -> 6.1728839 | P21: =O21/SUM($O$21:$O$25) -> 0.70601451
N22: =Summary!B15 -> Electricity | O22: =Summary!AA15 -> 2.3269512 | P22: =O22/SUM($O$21:$O$25) -> 0.26614162
N23: =Summary!B17 -> Coal | O23: =Summary!AA17 -> 0.084403921 | P23: =O23/SUM($O$21:$O$25) -> 0.0096535743
N24: Bioenergy and waste (not grid connected) | O24: =Summary!AA19 -> 0.11313979 | P24: =O24/SUM($O$21:$O$25) -> 0.012940197
N25: =Summary!B18 -> Oil | O25: =Summary!AA18 -> 0.045903076 | P25: =O25/SUM($O$21:$O$25) -> 0.0052500968
B32: Figure 3: CO2e emissions for Industrial & Commercial sector split by fuel in 2023 | N32: Table C3: CO2e emissions for Industrial & Commercial sector split by fuel in 2023
N33: (excluding fugitive emissions)
N34: =Summary!B22 -> I. ENERGY INDUSTRIAL AND COMMERCIAL | O34: MtCO2e | P34: %
N35: Electricity | O35: =Summary!AA24 -> 3.8712717 | P35: =O35/SUM($O$35:$O$40) -> 0.41176145
N36: Gas | O36: =Summary!AA23 -> 3.3333828 | P36: =O36/SUM($O$35:$O$40) -> 0.35454978
N37: Oil | O37: =Summary!AA28 -> 2.0459641 | P37: =O37/SUM($O$35:$O$40) -> 0.21761561
N38: Bioenergy and waste (not grid connected) | O38: =Summary!AA29 -> 0.083124727 | P38: =O38/SUM($O$35:$O$40) -> 0.0088414249
N39: Large industrial gas | O39: =Summary!AA25 -> 0.0097394471 | P39: =O39/SUM($O$35:$O$40) -> 0.0010359203
N40: Coal | O40: =Summary!AA27 -> 0.05825137 | P40: =O40/SUM($O$35:$O$40) -> 0.0061958112
B48: Figure 4: CO2e emissions for Transport sector in 2023 | N48: Table C4: CO2e emissions for Transport sector in 2023
N51: =Summary!B38 -> II. TRANSPORT | O51: MtCO2e | P51: %
N52: =Summary!B39 -> Road transport (non electric) | O52: =Summary!AA39 -> 6.6461607 | P52: =O52/SUM($O$52:$O$57) -> 0.77284239
N53: =Summary!B43 -> Aviation | O53: =Summary!AA43 -> 0.81117214 | P53: =O53/SUM($O$52:$O$57) -> 0.094326371
